<?xml version="1.0" encoding="utf-8"?>
<!-- This URDF was automatically created by SolidWorks to URDF Exporter! Originally created by Stephen Brawner (brawner@gmail.com) 
     Commit Version: 1.6.0-4-g7f85cfe  Build Version: 1.6.7995.38578
     For more information, please see http://wiki.ros.org/sw_urdf_exporter -->
<robot
  name="bot">
  <link
    name="base_link">
    <inertial>
      <origin
        xyz="0.0175258848470044 -6.93889390390723E-18 -0.0434907756108515"
        rpy="0 0 0" />
      <mass
        value="31.8459124902102" />
      <inertia
        ixx="0.576724606534719"
        ixy="-2.98054260107805E-17"
        ixz="0.0257206071314688"
        iyy="1.8511480910675"
        iyz="6.08510112063227E-18"
        izz="2.37865353514719" />
    </inertial>
    <visual>
      <origin
        xyz="0 0 0"
        rpy="0 0 0" />
      <geometry>
        <mesh
          filename="package://bot/meshes/base_link.STL" />
      </geometry>
      <material
        name="">
        <color
          rgba="0.792156862745098 0.819607843137255 0.933333333333333 1" />
      </material>
    </visual>
    <collision>
      <origin
        xyz="0 0 0"
        rpy="0 0 0" />
      <geometry>
        <mesh
          filename="package://bot/meshes/base_link.STL" />
      </geometry>
    </collision>
  </link>
  <link
    name="linkleft">
    <inertial>
      <origin
        xyz="-0.11696105411945 0.25527027027027 -0.03909954689"
        rpy="0 0 0" />
      <mass
        value="1.0461503536454" />
      <inertia
        ixx="0.003498401161919"
        ixy="2.53035420170816E-18"
        ixz="8.26739449559682E-21"
        iyy="0.00657802377771899"
        iyz="-6.7190252862076E-19"
        izz="0.003498401161919" />
    </inertial>
    <visual>
      <origin
        xyz="0 0 0"
        rpy="0 0 0" />
      <geometry>
        <mesh
          filename="package://bot/meshes/linkleft.STL" />
      </geometry>
      <material
        name="">
        <color
          rgba="0.792156862745098 0.819607843137255 0.933333333333333 1" />
      </material>
    </visual>
    <collision>
      <origin
        xyz="0 0 0"
        rpy="0 0 0" />
      <geometry>
        <mesh
          filename="package://bot/meshes/linkleft.STL" />
      </geometry>
    </collision>
  </link>
  <joint
    name="leftjoint"
    type="continuous">
    <origin
      xyz="0 0 0"
      rpy="0 0 0" />
    <parent
      link="base_link" />
    <child
      link="linkleft" />
    <axis
      xyz="0 -1 0" />
    <limit
      effort="1"
      velocity="1" />
  </joint>
  <link
    name="linkright">
    <inertial>
      <origin
        xyz="6.24500451351651E-17 0.0147297297297297 -4.85722573273506E-17"
        rpy="0 0 0" />
      <mass
        value="1.0461503536454" />
      <inertia
        ixx="0.00349840116191899"
        ixy="6.79632873406198E-19"
        ixz="-6.33351239789669E-19"
        iyy="0.00657802377771899"
        iyz="2.95254314555468E-19"
        izz="0.00349840116191899" />
    </inertial>
    <visual>
      <origin
        xyz="0 0 0"
        rpy="0 0 0" />
      <geometry>
        <mesh
          filename="package://bot/meshes/linkright.STL" />
      </geometry>
      <material
        name="">
        <color
          rgba="0.792156862745098 0.819607843137255 0.933333333333333 1" />
      </material>
    </visual>
    <collision>
      <origin
        xyz="0 0 0"
        rpy="0 0 0" />
      <geometry>
        <mesh
          filename="package://bot/meshes/linkright.STL" />
      </geometry>
    </collision>
  </link>
  <joint
    name="rightjoint"
    type="continuous">
    <origin
      xyz="-0.11696105411945 -0.27 -0.03909954689"
      rpy="0 0 0" />
    <parent
      link="base_link" />
    <child
      link="linkright" />
    <axis
      xyz="0 -1 0" />
  </joint>
</robot>